Workbook

Sheet 表单1
A1: 文物编号 | B1: 纹饰 | C1: 类型 | D1: 颜色 | E1: 表面风化
A2: 01 | B2: C | C2: 高钾 | D2: 蓝绿 | E2: 无风化
A3: 02 | B3: A | C3: 铅钡 | D3: 浅蓝 | E3: 风化
A4: 03 | B4: A | C4: 高钾 | D4: 蓝绿 | E4: 无风化
A5: 04 | B5: A | C5: 高钾 | D5: 蓝绿 | E5: 无风化
A6: 05 | B6: A | C6: 高钾 | D6: 蓝绿 | E6: 无风化
A7: 06 | B7: A | C7: 高钾 | D7: 蓝绿 | E7: 无风化
A8: 07 | B8: B | C8: 高钾 | D8: 蓝绿 | E8: 风化
A9: 08 | B9: C | C9: 铅钡 | D9: 紫 | E9: 风化
A10: 09 | B10: B | C10: 高钾 | D10: 蓝绿 | E10: 风化
A11: 10 | B11: B | C11: 高钾 | D11: 蓝绿 | E11: 风化
A12: 11 | B12: C | C12: 铅钡 | D12: 浅蓝 | E12: 风化
... A19: 18 | B19: A | C19: 高钾 | D19: 深蓝 | E19: 无风化
A20: 19 | B20: A | C20: 铅钡 | E20: 风化
A21: 20 | B21: A | C21: 铅钡 | D21: 浅蓝 | E21: 无风化
A22: 21 | B22: A | C22: 高钾 | D22: 蓝绿 | E22: 无风化
A23: 22 | B23: B | C23: 高钾 | D23: 蓝绿 | E23: 风化
A24: 23 | B24: A | C24: 铅钡 | D24: 蓝绿 | E24: 风化
A25: 24 | B25: C | C25: 铅钡 | D25: 紫 | E25: 无风化
A26: 25 | B26: C | C26: 铅钡 | D26: 浅蓝 | E26: 风化
A27: 26 | B27: C | C27: 铅钡 | D27: 紫 | E27: 风化
A28: 27 | B28: B | C28: 高钾 | D28: 蓝绿 | E28: 风化
A29: 28 | B29: A | C29: 铅钡 | D29: 浅蓝 | E29: 风化
A30: 29 | B30: A | C30: 铅钡 | D30: 浅蓝 | E30: 风化
A31: 30 | B31: A | C31: 铅钡 | D31: 深蓝 | E31: 无风化
A32: 31 | B32: C | C32: 铅钡 | D32: 紫 | E32: 无风化
... A40: 39 | B40: C | C40: 铅钡 | D40: 深绿 | E40: 风化
A41: 40 | B41: C | C41: 铅钡 | E41: 风化
A42: 41 | B42: C | C42: 铅钡 | D42: 浅绿 | E42: 风化
A43: 42 | B43: A | C43: 铅钡 | D43: 浅蓝 | E43: 风化
A44: 43 | B44: C | C44: 铅钡 | D44: 浅蓝 | E44: 风化
A45: 44 | B45: A | C45: 铅钡 | D45: 浅蓝 | E45: 风化
A46: 45 | B46: A | C46: 铅钡 | D46: 浅蓝 | E46: 无风化
A47: 46 | B47: A | C47: 铅钡 | D47: 浅蓝 | E47: 无风化
A48: 47 | B48: A | C48: 铅钡 | D48: 浅蓝 | E48: 无风化
A49: 48 | B49: A | C49: 铅钡 | E49: 风化
A50: 49 | B50: A | C50: 铅钡 | D50: 黑 | E50: 风化
A51: 50 | B51: A | C51: 铅钡 | D51: 黑 | E51: 风化
A52: 51 | B52: C | C52: 铅钡 | D52: 浅蓝 | E52: 风化
A53: 52 | B53: C | C53: 铅钡 | D53: 浅蓝 | E53: 风化
...

Sheet 表单2
A1: 文物采样点 | B1: 文物编号 | C1: 类型 | D1: 表面风化 | E1: 二氧化硅(SiO2) | F1: 氧化钠(Na2O) | G1: 氧化钾(K2O) | H1: 氧化钙(CaO) | I1: 氧化镁(MgO) | J1: 氧化铝(Al2O3) | K1: 氧化铁(Fe2O3) | L1: 氧化铜(CuO) | M1: 氧化铅(PbO) | N1: 氧化钡(BaO) | O1: 五氧化二磷(P2O5) | P1: 氧化锶(SrO) | Q1: 氧化锡(SnO2) | R1: 二氧化硫(SO2)
A2: 01 | B2: =LEFT(A2,2) -> 01 | C2: =VLOOKUP(B2,表单1!$A$1:$E$59,3,FALSE) -> 高钾 | D2: =VLOOKUP(B2,表单1!$A$1:$E$59,5,FALSE) -> 无风化 | E2: 69.33 | F2: 0.01 | G2: 9.99 | H2: 6.32 | I2: 0.87 | J2: 3.93 | K2: 1.74 | L2: 3.87 | M2: 0.01 | N2: 0.01 | O2: 1.17 | P2: 0.01 | Q2: 0.01 | R2: 0.39
A3: 02 | B3: =LEFT(A3,2) -> 02 | C3: =VLOOKUP(B3,表单1!$A$1:$E$59,3,FALSE) -> 铅钡 | D3: =VLOOKUP(B3,表单1!$A$1:$E$59,5,FALSE) -> 风化 | E3: 36.28 | F3: 0.01 | G3: 1.05 | H3: 2.34 | I3: 1.18 | J3: 5.73 | K3: 1.86 | L3: 0.26 | M3: 47.43 | N3: 0.01 | O3: 3.57 | P3: 0.19 | Q3: 0.01 | R3: 0.01
A4: 03部位1 | B4: =LEFT(A4,2) -> 03 | C4: =VLOOKUP(B4,表单1!$A$1:$E$59,3,FALSE) -> 高钾 | D4: =VLOOKUP(B4,表单1!$A$1:$E$59,5,FALSE) -> 无风化 | E4: 87.05 | F4: 0.01 | G4: 5.19 | H4: 2.01 | I4: 0.01 | J4: 4.06 | K4: 0.01 | L4: 0.78 | M4: 0.25 | N4: 0.01 | O4: 0.66 | P4: 0.01 | Q4: 0.01 | R4: 0.01
A5: 03部位2 | B5: =LEFT(A5,2) -> 03 | C5: =VLOOKUP(B5,表单1!$A$1:$E$59,3,FALSE) -> 高钾 | D5: =VLOOKUP(B5,表单1!$A$1:$E$59,5,FALSE) -> 无风化 | E5: 61.71 | F5: 0.01 | G5: 12.37 | H5: 5.87 | I5: 1.11 | J5: 5.5 | K5: 2.16 | L5: 5.09 | M5: 1.41 | N5: 2.86 | O5: 0.7 | P5: 0.1 | Q5: 0.01 | R5: 0.01
A6: 04 | B6: =LEFT(A6,2) -> 04 | C6: =VLOOKUP(B6,表单1!$A$1:$E$59,3,FALSE) -> 高钾 | D6: =VLOOKUP(B6,表单1!$A$1:$E$59,5,FALSE) -> 无风化 | E6: 65.88 | F6: 0.01 | G6: 9.67 | H6: 7.12 | I6: 1.56 | J6: 6.44 | K6: 2.06 | L6: 2.18 | M6: 0.01 | N6: 0.01 | O6: 0.79 | P6: 0.01 | Q6: 0.01 | R6: 0.36
A7: 05 | B7: =LEFT(A7,2) -> 05 | C7: =VLOOKUP(B7,表单1!$A$1:$E$59,3,FALSE) -> 高钾 | D7: =VLOOKUP(B7,表单1!$A$1:$E$59,5,FALSE) -> 无风化 | E7: 61.58 | F7: 0.01 | G7: 10.95 | H7: 7.35 | I7: 1.77 | J7: 7.5 | K7: 2.62 | L7: 3.27 | M7: 0.01 | N7: 0.01 | O7: 0.94 | P7: 0.06 | Q7: 0.01 | R7: 0.47
A8: 06部位1 | B8: =LEFT(A8,2) -> 06 | C8: =VLOOKUP(B8,表单1!$A$1:$E$59,3,FALSE) -> 高钾 | D8: =VLOOKUP(B8,表单1!$A$1:$E$59,5,FALSE) -> 无风化 | E8: 67.65 | F8: 0.01 | G8: 7.37 | H8: 0.01 | I8: 1.98 | J8: 11.15 | K8: 2.39 | L8: 2.51 | M8: 0.2 | N8: 1.38 | O8: 4.18 | P8: 0.11 | Q8: 0.01 | R8: 0.01
A9: 06部位2 | B9: =LEFT(A9,2) -> 06 | C9: =VLOOKUP(B9,表单1!$A$1:$E$59,3,FALSE) -> 高钾 | D9: =VLOOKUP(B9,表单1!$A$1:$E$59,5,FALSE) -> 无风化 | E9: 59.81 | F9: 0.01 | G9: 7.68 | H9: 5.41 | I9: 1.73 | J9: 10.05 | K9: 6.04 | L9: 2.18 | M9: 0.35 | N9: 0.97 | O9: 4.5 | P9: 0.12 | Q9: 0.01 | R9: 0.01
A10: 07 | B10: =LEFT(A10,2) -> 07 | C10: =VLOOKUP(B10,表单1!$A$1:$E$59,3,FALSE) -> 高钾 | D10: =VLOOKUP(B10,表单1!$A$1:$E$59,5,FALSE) -> 风化 | E10: 92.63 | F10: 0.01 | G10: 0.01 | H10: 1.07 | I10: 0.01 | J10: 1.98 | K10: 0.17 | L10: 3.24 | M10: 0.01 | N10: 0.01 | O10: 0.61 | P10: 0.01 | Q10: 0.01 | R10: 0.01
A11: 08 | B11: =LEFT(A11,2) -> 08 | C11: =VLOOKUP(B11,表单1!$A$1:$E$59,3,FALSE) -> 铅钡 | D11: =VLOOKUP(B11,表单1!$A$1:$E$59,5,FALSE) -> 风化 | E11: 20.14 | F11: 0.01 | G11: 0.01 | H11: 1.48 | I11: 0.01 | J11: 1.34 | K11: 0.01 | L11: 10.41 | M11: 28.68 | N11: 31.23 | O11: 3.59 | P11: 0.37 | Q11: 0.01 | R11: 2.58
A12: 08严重风化点 | B12: =LEFT(A12,2) -> 08 | C12: =VLOOKUP(B12,表单1!$A$1:$E$59,3,FALSE) -> 铅钡 | D12: =VLOOKUP(B12,表单1!$A$1:$E$59,5,FALSE) -> 风化 | E12: 4.61 | F12: 0.01 | G12: 0.01 | H12: 3.19 | I12: 0.01 | J12: 1.11 | K12: 0.01 | L12: 3.14 | M12: 32.45 | N12: 30.62 | O12: 7.56 | P12: 0.53 | Q12: 0.01 | R12: 15.03
A13: 09 | B13: =LEFT(A13,2) -> 09 | C13: =VLOOKUP(B13,表单1!$A$1:$E$59,3,FALSE) -> 高钾 | D13: =VLOOKUP(B13,表单1!$A$1:$E$59,5,FALSE) -> 风化 | E13: 95.02 | F13: 0.01 | G13: 0.59 | H13: 0.62 | I13: 0.01 | J13: 1.32 | K13: 0.32 | L13: 1.55 | M13: 0.01 | N13: 0.01 | O13: 0.35 | P13: 0.01 | Q13: 0.01 | R13: 0.01
... A68: 58 | B68: =LEFT(A68,2) -> 58 | C68: =VLOOKUP(B68,表单1!$A$1:$E$59,3,FALSE) -> 铅钡 | D68: =VLOOKUP(B68,表单1!$A$1:$E$59,5,FALSE) -> 风化 | E68: 30.39 | F68: 0.01 | G68: 0.34 | H68: 3.49 | I68: 0.79 | J68: 3.52 | K68: 0.86 | L68: 3.13 | M68: 39.35 | N68: 7.66 | O68: 8.99 | P68: 0.24 | Q68: 0.01 | R68: 0.01

Sheet 表单2 (2)
A1: 文物采样点 | B1: 文物编号 | C1: 类型 | D1: 表面风化 | E1: 二氧化硅(SiO2) | F1: 氧化钠(Na2O) | G1: 氧化钾(K2O) | H1: 氧化钙(CaO) | I1: 氧化镁(MgO) | J1: 氧化铝(Al2O3) | K1: 氧化铁(Fe2O3) | L1: 氧化铜(CuO) | M1: 氧化铅(PbO) | N1: 氧化钡(BaO) | O1: 五氧化二磷(P2O5) | P1: 氧化锶(SrO) | Q1: 氧化锡(SnO2) | R1: 二氧化硫(SO2)
A2: 01 | B2: =LEFT(A2,2) -> 01 | C2: =VLOOKUP(B2,表单1!$A$1:$E$59,3,FALSE) -> 高钾 | D2: =VLOOKUP(B2,表单1!$A$1:$E$59,5,FALSE) -> 无风化 | E2: 69.33 | F2: 0.01 | G2: 9.99 | H2: 6.32 | I2: 0.87 | J2: 3.93 | K2: 1.74 | L2: 3.87 | M2: 0.01 | N2: 0.01 | O2: 1.17 | P2: 0.01 | Q2: 0.01 | R2: 0.39
A3: 03部位1 | B3: =LEFT(A3,2) -> 03 | C3: =VLOOKUP(B3,表单1!$A$1:$E$59,3,FALSE) -> 高钾 | D3: =VLOOKUP(B3,表单1!$A$1:$E$59,5,FALSE) -> 无风化 | E3: 87.05 | F3: 0.01 | G3: 5.19 | H3: 2.01 | I3: 0.01 | J3: 4.06 | K3: 0.01 | L3: 0.78 | M3: 0.25 | N3: 0.01 | O3: 0.66 | P3: 0.01 | Q3: 0.01 | R3: 0.01
A4: 03部位2 | B4: =LEFT(A4,2) -> 03 | C4: =VLOOKUP(B4,表单1!$A$1:$E$59,3,FALSE) -> 高钾 | D4: =VLOOKUP(B4,表单1!$A$1:$E$59,5,FALSE) -> 无风化 | E4: 61.71 | F4: 0.01 | G4: 12.37 | H4: 5.87 | I4: 1.11 | J4: 5.5 | K4: 2.16 | L4: 5.09 | M4: 1.41 | N4: 2.86 | O4: 0.7 | P4: 0.1 | Q4: 0.01 | R4: 0.01
A5: 04 | B5: =LEFT(A5,2) -> 04 | C5: =VLOOKUP(B5,表单1!$A$1:$E$59,3,FALSE) -> 高钾 | D5: =VLOOKUP(B5,表单1!$A$1:$E$59,5,FALSE) -> 无风化 | E5: 65.88 | F5: 0.01 | G5: 9.67 | H5: 7.12 | I5: 1.56 | J5: 6.44 | K5: 2.06 | L5: 2.18 | M5: 0.01 | N5: 0.01 | O5: 0.79 | P5: 0.01 | Q5: 0.01 | R5: 0.36
A6: 05 | B6: =LEFT(A6,2) -> 05 | C6: =VLOOKUP(B6,表单1!$A$1:$E$59,3,FALSE) -> 高钾 | D6: =VLOOKUP(B6,表单1!$A$1:$E$59,5,FALSE) -> 无风化 | E6: 61.58 | F6: 0.01 | G6: 10.95 | H6: 7.35 | I6: 1.77 | J6: 7.5 | K6: 2.62 | L6: 3.27 | M6: 0.01 | N6: 0.01 | O6: 0.94 | P6: 0.06 | Q6: 0.01 | R6: 0.47
A7: 06部位1 | B7: =LEFT(A7,2) -> 06 | C7: =VLOOKUP(B7,表单1!$A$1:$E$59,3,FALSE) -> 高钾 | D7: =VLOOKUP(B7,表单1!$A$1:$E$59,5,FALSE) -> 无风化 | E7: 67.65 | F7: 0.01 | G7: 7.37 | H7: 0.01 | I7: 1.98 | J7: 11.15 | K7: 2.39 | L7: 2.51 | M7: 0.2 | N7: 1.38 | O7: 4.18 | P7: 0.11 | Q7: 0.01 | R7: 0.01
A8: 06部位2 | B8: =LEFT(A8,2) -> 06 | C8: =VLOOKUP(B8,表单1!$A$1:$E$59,3,FALSE) -> 高钾 | D8: =VLOOKUP(B8,表单1!$A$1:$E$59,5,FALSE) -> 无风化 | E8: 59.81 | F8: 0.01 | G8: 7.68 | H8: 5.41 | I8: 1.73 | J8: 10.05 | K8: 6.04 | L8: 2.18 | M8: 0.35 | N8: 0.97 | O8: 4.5 | P8: 0.12 | Q8: 0.01 | R8: 0.01
A9: 13 | B9: =LEFT(A9,2) -> 13 | C9: =VLOOKUP(B9,表单1!$A$1:$E$59,3,FALSE) -> 高钾 | D9: =VLOOKUP(B9,表单1!$A$1:$E$59,5,FALSE) -> 无风化 | E9: 59.01 | F9: 2.86 | G9: 12.53 | H9: 8.7 | I9: 0.01 | J9: 6.16 | K9: 2.88 | L9: 4.73 | M9: 0.01 | N9: 0.01 | O9: 1.27 | P9: 0.01 | Q9: 0.01 | R9: 0.01
A10: 14 | B10: =LEFT(A10,2) -> 14 | C10: =VLOOKUP(B10,表单1!$A$1:$E$59,3,FALSE) -> 高钾 | D10: =VLOOKUP(B10,表单1!$A$1:$E$59,5,FALSE) -> 无风化 | E10: 62.47 | F10: 3.38 | G10: 12.28 | H10: 8.23 | I10: 0.66 | J10: 9.23 | K10: 0.5 | L10: 0.47 | M10: 1.62 | N10: 0.01 | O10: 0.16 | P10: 0.01 | Q10: 0.01 | R10: 0.01
A11: 16 | B11: =LEFT(A11,2) -> 16 | C11: =VLOOKUP(B11,表单1!$A$1:$E$59,3,FALSE) -> 高钾 | D11: =VLOOKUP(B11,表单1!$A$1:$E$59,5,FALSE) -> 无风化 | E11: 65.18 | F11: 2.1 | G11: 14.52 | H11: 8.27 | I11: 0.52 | J11: 6.18 | K11: 0.42 | L11: 1.07 | M11: 0.11 | N11: 0 | O11: 0.01 | P11: 0.04 | Q11: 0.01 | R11: 0.01
A12: 18 | B12: =LEFT(A12,2) -> 18 | C12: =VLOOKUP(B12,表单1!$A$1:$E$59,3,FALSE) -> 高钾 | D12: =VLOOKUP(B12,表单1!$A$1:$E$59,5,FALSE) -> 无风化 | E12: 79.46 | F12: 0.01 | G12: 9.42 | H12: 0.01 | I12: 1.53 | J12: 3.05 | K12: 0.01 | L12: 0.01 | M12: 0.01 | N12: 0.01 | O12: 1.36 | P12: 0.07 | Q12: 2.36 | R12: 0.01
A13: 21 | B13: =LEFT(A13,2) -> 21 | C13: =VLOOKUP(B13,表单1!$A$1:$E$59,3,FALSE) -> 高钾 | D13: =VLOOKUP(B13,表单1!$A$1:$E$59,5,FALSE) -> 无风化 | E13: 76.68 | F13: 0.01 | G13: 0.01 | H13: 4.71 | I13: 1.22 | J13: 6.19 | K13: 2.37 | L13: 3.28 | M13: 1 | N13: 1.97 | O13: 1.1 | P13: 0.01 | Q13: 0.01 | R13: 0.01
... A36: 55 | B36: =LEFT(A36,2) -> 55 | C36: =VLOOKUP(B36,表单1!$A$1:$E$59,3,FALSE) -> 铅钡 | D36: =VLOOKUP(B36,表单1!$A$1:$E$59,5,FALSE) -> 无风化 | E36: 49.01 | F36: 2.71 | G36: 0.01 | H36: 1.13 | I36: 0.01 | J36: 1.45 | K36: 0.01 | L36: 0.86 | M36: 32.92 | N36: 7.95 | O36: 0.35 | P36: 0.01 | Q36: 0.01 | R36: 0.01

Sheet 表单2 (4)
A1: 文物采样点 | B1: 文物编号 | C1: 类型 | D1: 表面风化 | E1: 二氧化硅(SiO2) | F1: 氧化钠(Na2O) | G1: 氧化钾(K2O) | H1: 氧化钙(CaO) | I1: 氧化镁(MgO) | J1: 氧化铝(Al2O3) | K1: 氧化铁(Fe2O3) | L1: 氧化铜(CuO) | M1: 氧化铅(PbO) | N1: 氧化钡(BaO) | O1: 五氧化二磷(P2O5) | P1: 氧化锶(SrO) | Q1: 氧化锡(SnO2) | R1: 二氧化硫(SO2)
A2: 01 | B2: =LEFT(A2,2) -> 01 | C2: =VLOOKUP(B2,表单1!$A$1:$E$59,3,FALSE) -> 高钾 | D2: =VLOOKUP(B2,表单1!$A$1:$E$59,5,FALSE) -> 无风化 | E2: 69.33 | F2: 0.04 | G2: 9.99 | H2: 6.32 | I2: 0.87 | J2: 3.93 | K2: 1.74 | L2: 3.87 | M2: 0.04 | N2: 0.04 | O2: 1.17 | P2: 0.04 | Q2: 0.04 | R2: 0.39
A3: 03部位1 | B3: =LEFT(A3,2) -> 03 | C3: =VLOOKUP(B3,表单1!$A$1:$E$59,3,FALSE) -> 高钾 | D3: =VLOOKUP(B3,表单1!$A$1:$E$59,5,FALSE) -> 无风化 | E3: 87.05 | F3: 0.04 | G3: 5.19 | H3: 2.01 | I3: 0.04 | J3: 4.06 | K3: 0.04 | L3: 0.78 | M3: 0.25 | N3: 0.04 | O3: 0.66 | P3: 0.04 | Q3: 0.04 | R3: 0.04
A4: 03部位2 | B4: =LEFT(A4,2) -> 03 | C4: =VLOOKUP(B4,表单1!$A$1:$E$59,3,FALSE) -> 高钾 | D4: =VLOOKUP(B4,表单1!$A$1:$E$59,5,FALSE) -> 无风化 | E4: 61.71 | F4: 0.04 | G4: 12.37 | H4: 5.87 | I4: 1.11 | J4: 5.5 | K4: 2.16 | L4: 5.09 | M4: 1.41 | N4: 2.86 | O4: 0.7 | P4: 0.1 | Q4: 0.04 | R4: 0.04
A5: 04 | B5: =LEFT(A5,2) -> 04 | C5: =VLOOKUP(B5,表单1!$A$1:$E$59,3,FALSE) -> 高钾 | D5: =VLOOKUP(B5,表单1!$A$1:$E$59,5,FALSE) -> 无风化 | E5: 65.88 | F5: 0.04 | G5: 9.67 | H5: 7.12 | I5: 1.56 | J5: 6.44 | K5: 2.06 | L5: 2.18 | M5: 0.04 | N5: 0.04 | O5: 0.79 | P5: 0.04 | Q5: 0.04 | R5: 0.36
A6: 05 | B6: =LEFT(A6,2) -> 05 | C6: =VLOOKUP(B6,表单1!$A$1:$E$59,3,FALSE) -> 高钾 | D6: =VLOOKUP(B6,表单1!$A$1:$E$59,5,FALSE) -> 无风化 | E6: 61.58 | F6: 0.04 | G6: 10.95 | H6: 7.35 | I6: 1.77 | J6: 7.5 | K6: 2.62 | L6: 3.27 | M6: 0.04 | N6: 0.04 | O6: 0.94 | P6: 0.06 | Q6: 0.04 | R6: 0.47
A7: 06部位1 | B7: =LEFT(A7,2) -> 06 | C7: =VLOOKUP(B7,表单1!$A$1:$E$59,3,FALSE) -> 高钾 | D7: =VLOOKUP(B7,表单1!$A$1:$E$59,5,FALSE) -> 无风化 | E7: 67.65 | F7: 0.04 | G7: 7.37 | H7: 0.04 | I7: 1.98 | J7: 11.15 | K7: 2.39 | L7: 2.51 | M7: 0.2 | N7: 1.38 | O7: 4.18 | P7: 0.11 | Q7: 0.04 | R7: 0.04
A8: 06部位2 | B8: =LEFT(A8,2) -> 06 | C8: =VLOOKUP(B8,表单1!$A$1:$E$59,3,FALSE) -> 高钾 | D8: =VLOOKUP(B8,表单1!$A$1:$E$59,5,FALSE) -> 无风化 | E8: 59.81 | F8: 0.04 | G8: 7.68 | H8: 5.41 | I8: 1.73 | J8: 10.05 | K8: 6.04 | L8: 2.18 | M8: 0.35 | N8: 0.97 | O8: 4.5 | P8: 0.12 | Q8: 0.04 | R8: 0.04
A9: 13 | B9: =LEFT(A9,2) -> 13 | C9: =VLOOKUP(B9,表单1!$A$1:$E$59,3,FALSE) -> 高钾 | D9: =VLOOKUP(B9,表单1!$A$1:$E$59,5,FALSE) -> 无风化 | E9: 59.01 | F9: 2.86 | G9: 12.53 | H9: 8.7 | I9: 0.04 | J9: 6.16 | K9: 2.88 | L9: 4.73 | M9: 0.04 | N9: 0.04 | O9: 1.27 | P9: 0.04 | Q9: 0.04 | R9: 0.04
A10: 14 | B10: =LEFT(A10,2) -> 14 | C10: =VLOOKUP(B10,表单1!$A$1:$E$59,3,FALSE) -> 高钾 | D10: =VLOOKUP(B10,表单1!$A$1:$E$59,5,FALSE) -> 无风化 | E10: 62.47 | F10: 3.38 | G10: 12.28 | H10: 8.23 | I10: 0.66 | J10: 9.23 | K10: 0.5 | L10: 0.47 | M10: 1.62 | N10: 0.04 | O10: 0.16 | P10: 0.04 | Q10: 0.04 | R10: 0.04
A11: 16 | B11: =LEFT(A11,2) -> 16 | C11: =VLOOKUP(B11,表单1!$A$1:$E$59,3,FALSE) -> 高钾 | D11: =VLOOKUP(B11,表单1!$A$1:$E$59,5,FALSE) -> 无风化 | E11: 65.18 | F11: 2.1 | G11: 14.52 | H11: 8.27 | I11: 0.52 | J11: 6.18 | K11: 0.42 | L11: 1.07 | M11: 0.11 | N11: 0 | O11: 0.04 | P11: 0.04 | Q11: 0.04 | R11: 0.04
A12: 18 | B12: =LEFT(A12,2) -> 18 | C12: =VLOOKUP(B12,表单1!$A$1:$E$59,3,FALSE) -> 高钾 | D12: =VLOOKUP(B12,表单1!$A$1:$E$59,5,FALSE) -> 无风化 | E12: 79.46 | F12: 0.04 | G12: 9.42 | H12: 0.04 | I12: 1.53 | J12: 3.05 | K12: 0.04 | L12: 0.04 | M12: 0.04 | N12: 0.04 | O12: 1.36 | P12: 0.07 | Q12: 2.36 | R12: 0.04
A13: 21 | B13: =LEFT(A13,2) -> 21 | C13: =VLOOKUP(B13,表单1!$A$1:$E$59,3,FALSE) -> 高钾 | D13: =VLOOKUP(B13,表单1!$A$1:$E$59,5,FALSE) -> 无风化 | E13: 76.68 | F13: 0.04 | G13: 0.04 | H13: 4.71 | I13: 1.22 | J13: 6.19 | K13: 2.37 | L13: 3.28 | M13: 1 | N13: 1.97 | O13: 1.1 | P13: 0.04 | Q13: 0.04 | R13: 0.04
... A36: 55 | B36: =LEFT(A36,2) -> 55 | C36: =VLOOKUP(B36,表单1!$A$1:$E$59,3,FALSE) -> 铅钡 | D36: =VLOOKUP(B36,表单1!$A$1:$E$59,5,FALSE) -> 无风化 | E36: 49.01 | F36: 2.71 | G36: 0.04 | H36: 1.13 | I36: 0.04 | J36: 1.45 | K36: 0.04 | L36: 0.86 | M36: 32.92 | N36: 7.95 | O36: 0.35 | P36: 0.04 | Q36: 0.04 | R36: 0.04
